Workbook

Sheet 01.05.2025
A1: LAVOZIM | B1: F.I.O | C1: DEP
A2: Direktor | B2: Eshchanov Otabek Kamiljanovich | C2: Rahbariyat (IVS)
A3: Direktorning birinchi o‘rinbosari | B3: Tursunov Abror Askarovich | C3: Rahbariyat (IVS)
A4: Direktor o‘rinbosari | B4: Nazarov Nazirjon Baxtiyor ug‘li | C4: Rahbariyat (IVS)
A5: Bosh buxgalter | B5: Mengniyozov Farxod Axmad o‘g‘li | C5: Moliya-iqtisod bo‘limi
A6: Bosh buxgalter o‘rinbosari | B6: Egamberdiyev Samariddin Egamberdi o‘g‘li | C6: Moliya-iqtisod bo‘limi
A7: Bosh mutaxassis | B7: Yakushina Yelena Anatolevna | C7: Moliya-iqtisod bo‘limi
A8: Bosh mutaxassis | B8: Djalalova Zuxra Axrarovna | C8: Moliya-iqtisod bo‘limi
A9: Yetakchi mutaxassis | B9: Valiyev Komronxon Abbosovich | C9: Axborot xavfsizligi va sinov bo'limi
A10: 1-toifali mutaxassis | B10: Orziyev Orzibek Fazliddin o‘g‘li | C10: Axborot xavfsizligi va sinov bo'limi
A11: Axborot xavfsizligi bo'yicha yetakchi mutaxassis | B11: Abdugafurov Turgunboy Turdivayevich | C11: Axborot xavfsizligi va sinov bo'limi
A12: Axborot tizimlarini sinovdan o'tkazish bo'yicha yetakchi mutaxassis | B12: Abdulxayev Jayxuntilla Qudratilla o'g'li | C12: Axborot xavfsizligi va sinov bo'limi
... A198: 3-toifali mutaxassis (Toshkent vil.) | B198: Xo‘jamurodov Bobur Tolib o‘g‘li | C198: Hududlarga texnik va tarmoq xizmatlarini ko'rsatish bo'limi

Sheet Лист3
A2: okLAD | B2: 7179900
A3: pitaniye | B3: 1648000
A4: foizi | B4: 1.5
A5: Ustama | B5: =+B2*B4 -> 10769850
A6: Summa | B6: =+B2+B3+B5 -> 19597750
A7: -8.5 | B7: =+B6*91.5% -> 17931941
A11: 0.5 | B11: =+B7/2 -> 8965970.6

Sheet boshliqlar
A1: Bosh buxgalter | B1: 1 | C1: Mengniyozov Farxod Axmad o‘g‘li (o‘rindosh) (0.75)
A2: Bo‘lim boshlig‘i | B2: 1 | C2: Saydazimova Ziyoda Taxirovna
A3: Bo‘lim boshlig‘i | B3: 1 | C3: Ismailova Nafisa Amangeldiyevna (137)
A4: Ish boshqaruvchi | B4: 1 | C4: Abdukarimov Abduvali Abdug‘ani o‘g‘li
A5: Call markaz boshlig‘i | B5: 1 | C5: Begimov Suxrobjon Farxodovich
A6: Departament direktori | B6: 1 | C6: Abduqodirov Obid Yangiboyevich
A7: Backend boshqarmasi boshlig'i | B7: 1 | C7: Ahmatxonov Nasimxon Nabijon o‘g‘li
A8: Backend boshqarmasi boshlig'i o'rinbosari | B8: 1 | C8: Saidiy Jahongir Erkin o‘g‘li
A9: Frontend boshqarmasi boshlig'i | B9: 1 | C9: Ismoilov Dilmurod Baxtiyor o‘g‘li
A10: Frontend boshqarmasi boshlig'i o'rinbosari | B10: 1 | C10: Botirov Elmurod Mirzaxakim o‘g‘li
A11: Bo'lim boshlig'i | B11: 1 | C11: Sodiqov Xumoyunmirzo Nurilla o‘g‘li (0,75 stavka)
A12: Boshqarma boshlig'i | B12: 1 | C12: Qayumov Azimjon Abdulvosiyevich
... A24: Boshqarma boshlig‘i | B24: 1 | C24: Narzullayev Anvar Shuhrat o‘g‘li

Sheet liast----
A1: O‘zbekiston Respublikasi Iqtisodiyot va moliya vazirligi huzuridagi Axborot texnologiyalari markazi DUKning
A2: SHTAT JADVALI
D3: 01.05.2025-yil
A4: Tarkibiy tuzilmalarning nomi va lavozimlar nomi | B4: Shtat birliklarining soni | C4: Bir shtat birligi uchun tasdiqlangan razryadlar uchun belgilangan tarif koeffisenti bo'yicha lavozim oklad | D4: Shtat birliklarining soni bo'yicha lavozim okladi (so'm) | E4: Razryad | F4: F.I.Sh | G4: F.I.Sh
A5: 1 | B5: 2 | D5: 4 | E5: 3
A6: Rahbariyat (1.1.)
A7: Direktor | B7: 1 | C7: =+Лист4!C16 -> 9369400 | D7: =+Лист4!C16 -> 9369400 | E7: 16 | F7: Eshchanov Otabek Kamiljanovich | G7: Eshchanov Otabek Kamiljanovich (-)
A8: Direktorning birinchi o‘rinbosari | B8: 1 | C8: =+Лист4!C14 -> 8873900 | D8: =+Лист4!C14 -> 8873900 | E8: 15 | F8: Tursunov Abror Askarovich | G8: Tursunov Abror Askarovich
A9: Direktor o‘rinbosari | B9: 1 | C9: =+Лист4!$C$15 -> 8430300 | D9: =+Лист4!C15 -> 8430300 | E9: 15 | F9: Nazarov Nazirjon Baxtiyor ug‘li | G9: Nazarov Nazirjon Baxtiyor ug‘li
A10: Jami: | B10: =SUM(B7:B9) -> 3 | D10: =SUM(D7:D9) -> 26673600
A11: Moliya-iqtisod bo‘limi (2.1.)
A12: Bosh buxgalter | B12: 1 | C12: =+Лист4!$C$11 -> 7914100 | D12: =+B12*Лист4!$C$11 -> 7914100 | E12: 13 | F12: Mengniyozov Farxod Axmad o‘g‘li (o‘rindosh) (0.75) | G12: Mengniyozov Farxod Axmad o‘g‘li (o‘rindosh) (0.75)
A13: Bosh buxgalter o‘rinbosari | B13: 1 | C13: =+Лист4!$C$11 -> 7914100 | D13: =+B13*Лист4!$C$11 -> 7914100 | E13: 13 | F13: Djalalova Zuxra Axrarovna | G13: Djalalova Zuxra Axrarovna (137)
A14: Bosh mutaxassis | B14: 1 | C14: =+Лист4!$C$10 -> 7442800 | D14: =+B14*Лист4!$C$10 -> 7442800 | E14: 12 | F14: Yakushina Yelena Anatolevna | G14: Yakushina Yelena Anatolevna
A15: Bosh mutaxassis | B15: 1 | C15: =+Лист4!$C$10 -> 7442800 | D15: =+B15*Лист4!$C$10 -> 7442800 | E15: 12 | F15: Egamberdiyev Samariddin Egamberdi o‘g‘li | G15: Egamberdiyev Samariddin Egamberdi o‘g‘li
A16: Jami: | B16: =SUM(B12:B15) -> 4 | D16: =SUM(D12:D15) -> 30713800
A17: Axborot va kiberxavfsizlikni ta'minlash bo'limi (3.1.)
A18: Bo‘lim boshlig‘i | B18: 1 | C18: =+Лист4!$C$11 -> 7914100 | D18: =+B18*Лист4!$C$11 -> 7914100 | E18: 13 | F18: Valiyev Komronxon Abbosovich
A19: Yetakchi mutaxassis | B19: 1 | C19: =+Лист4!$C$9 -> 6978500 | D19: =+B19*Лист4!$C$9 -> 6978500 | E19: 11 | F19: Karimov Davron Farrux o‘g‘li | G19: Valiyev Komronxon Abbosovich (144)
A20: 1-toifali mutaxassis | B20: 1 | C20: =+Лист4!$C$8 -> 6524600 | D20: =+B20*Лист4!$C$8 -> 6524600 | E20: 10 | F20: Pozilxonov Azamat Alisher o‘g‘li | G20: Karimov Davron Farrux o‘g‘li
A21: Axborot xavfsizligi bo'yicha yetakchi mutaxassis | B21: 1 | C21: =+Лист4!$C$9 -> 6978500 | D21: =+B21*Лист4!$C$9 -> 6978500 | E21: 11 | F21: vakant
A22: Axborot tizimlarini sinovdan o'tkazish bo'yicha yetakchi mutaxassis | B22: 1 | C22: =+Лист4!$C$9 -> 6978500 | D22: =+B22*Лист4!$C$9 -> 6978500 | E22: 11 | F22: vakant
A23: Jami: | B23: =SUM(B18:B22) -> 5 | D23: =SUM(D18:D22) -> 35374200
A24: Ijro nazorati va murojaatlar bilan ishlash bo'limi(4.1.)
A25: Bo‘lim boshlig‘i | B25: 1 | C25: =+Лист4!$C$11 -> 7914100 | D25: =+B25*Лист4!$C$11 -> 7914100 | E25: 13 | F25: Saydazimova Ziyoda Taxirovna | G25: Saydazimova Ziyoda Taxirovna
A26: 2-toifali mutaxassis | B26: 1 | C26: =+Лист4!$C$7 -> 6081100 | D26: =+B26*Лист4!$C$7 -> 6081100 | E26: 9 | F26: Nurxodjayeva Gulnora To‘ychi qizi | G26: Nurxodjayeva Gulnora To‘ychi qizi
A27: Jami: | B27: =SUM(B25:B26) -> 2 | D27: =SUM(D25:D26) -> 13995200
A28: Inson resurslarini rivojlantirish bo‘limi (5.1.)
A29: Bo‘lim boshlig‘i | B29: 1 | C29: =+Лист4!$C$11 -> 7914100 | D29: =+B29*Лист4!$C$11 -> 7914100 | E29: 13 | F29: Ismailova Nafisa Amangeldiyevna | G29: Ismailova Nafisa Amangeldiyevna (137)
A30: Bosh mutaxassis | B30: 1 | C30: =+Лист4!$C$10 -> 7442800 | D30: =+B30*Лист4!$C$10 -> 7442800 | E30: 12 | F30: vakant
A31: Jami: | B31: =SUM(B29:B30) -> 2 | D31: =SUM(D29:D30) -> 15356900
A32: Bosh yuriskonsult (6.1.) | B32: 1 | C32: =+Лист4!$C$11 -> 7914100 | D32: =+B32*Лист4!$C$11 -> 7914100 | E32: 13
A33: Korporativ maslahatchi-marketolog (7.1.) | B33: 1 | C33: =+Лист4!$C$9 -> 6978500 | D33: =+B33*Лист4!$C$9 -> 6978500 | E33: 11 | F33: Mamatqulov Yorqin Komiljon o'g'li | G33: Mamatqulov Yorqin Komiljon o'g'li
A34: Korrupsiyaga qarshi kurashish bo'yicha mutaxassis (8.1.) | B34: 1 | C34: =+Лист4!$C$9 -> 6978500 | D34: =+B34*Лист4!$C$9 -> 6978500 | E34: 11 | F34: Eshniyozov Jamshid To‘lqinovich
A35: Ishlar boshqarish bo'limi (9.1.)
A36: Ish boshqaruvchi | B36: 1 | C36: =+Лист4!$C$11 -> 7914100 | D36: =+B36*Лист4!$C$11 -> 7914100 | E36: 13 | F36: Abdukarimov Abduvali Abdug‘ani o‘g‘li | G36: Abdukarimov Abduvali Abdug‘ani o‘g‘li
A37: Ombor mudiri | B37: 1 | C37: =+Лист4!C5 -> 5214800 | D37: =+Лист4!C22 -> 3476600 | E37: 7 | F37: Sa’dullayev Axrorxo‘ja Ubaydulla o‘g‘li | G37: Sa’dullayev Axrorxo‘ja Ubaydulla o‘g‘li
A38: Haydovchi 1-smena ( 1,5 smena) | B38: 1 | C38: =+Лист4!C21*1.5 -> 3465000 | D38: =+B39*Лист4!C21*1.5 -> 3465000 | E38: 1 | F38: Azimboyev Akobir Akrom o'g'li
A39: Haydovchi 1-smena ( 1,5 smena) | B39: 1 | C39: =+Лист4!C21*1.5 -> 3465000 | D39: =+B39*Лист4!C21*1.5 -> 3465000 | E39: 1 | F39: Mirabbosov Miraziz Forxod o‘g‘li
A40: Jami: | B40: =SUM(B36:B39) -> 4 | D40: =SUM(D36:D39) -> 18320700
...

Sheet Лист1 (2)
A6: O‘zbekiston Respublikasi Iqtisodiyot va moliya vazirligi huzuridagi Axborot texnologiyalari markazi DUKning
A7: SHTAT JADVALI
A9: Tarkibiy tuzilmalarning nomi va lavozimlar nomi | B9: Shtat birliklarining soni | C9: Bir shtat birligi uchun tasdiqlangan razryadlar uchun belgilangan tarif koeffisenti bo'yicha lavozim oklad | D9: Shtat birliklarining soni bo'yicha lavozim okladi (so'm) | E9: Razryad | F9: F.I.Sh
A10: 1 | B10: 2 | D10: 4 | E10: 3
A11: Rahbariyat (1.1.)
A12: Direktor | B12: 1 | C12: =+Лист4!C16 -> 9369400 | D12: =+Лист4!C16 -> 9369400 | E12: 16 | F12: Eshchanov Otabek Kamiljanovich
A13: Direktorning birinchi o‘rinbosari | B13: 1 | C13: =+Лист4!C14 -> 8873900 | D13: =+Лист4!C14 -> 8873900 | E13: 15 | F13: Tursunov Abror Askarovich
A14: Direktor o‘rinbosari | B14: 1 | C14: =+Лист4!$C$15 -> 8430300 | D14: =+Лист4!C15 -> 8430300 | E14: 15 | F14: Nazarov Nazirjon Baxtiyor ug‘li
A15: Jami: | B15: =SUM(B12:B14) -> 3 | D15: =SUM(D12:D14) -> 26673600
A16: Moliya-iqtisod bo‘limi (2.1.)
A17: Bo‘lim boshlig‘i-Bosh buxgalter | B17: 1 | C17: =+Лист4!$C$13 -> 8388800 | D17: =+B17*Лист4!$C$13 -> 8388800 | E17: 14 | F17: Mengniyozov Farxod Axmad o‘g‘li (o‘rindosh) (0.75)
A18: Bo‘lim boshlig‘i o‘rinbosari-Bosh buxgalter o‘rinbosari | B18: 1 | C18: =+Лист4!$C$11 -> 7914100 | D18: =+B18*Лист4!$C$11 -> 7914100 | E18: 13 | F18: Djalalova Zuxra Axrarovna
A19: Bosh mutaxassis | B19: 1 | C19: =+Лист4!$C$10 -> 7442800 | D19: =+B19*Лист4!$C$10 -> 7442800 | E19: 12 | F19: Yakushina Yelena Anatolevna
A20: Bosh mutaxassis | B20: 1 | C20: =+Лист4!$C$10 -> 7442800 | D20: =+B20*Лист4!$C$10 -> 7442800 | E20: 12 | F20: Egamberdiyev Samariddin Egamberdi o‘g‘li
A21: Jami: | B21: =SUM(B17:B20) -> 4 | D21: =SUM(D17:D20) -> 31188500
A22: Axborot va kiberxavfsizlikni ta'minlash bo'limi (3.1.)
A23: Bo‘lim boshlig‘i | B23: 1 | C23: =+Лист4!$C$13 -> 8388800 | D23: =+B23*Лист4!$C$13 -> 8388800 | E23: 14 | F23: Valiyev Komronxon Abbosovich
A24: Yetakchi mutaxassis | B24: 1 | C24: =+Лист4!$C$9 -> 6978500 | D24: =+B24*Лист4!$C$9 -> 6978500 | E24: 11 | F24: Karimov Davron Farrux o‘g‘li
A25: 1-toifali mutaxassis | B25: 1 | C25: =+Лист4!$C$8 -> 6524600 | D25: =+B25*Лист4!$C$8 -> 6524600 | E25: 10 | F25: Pozilxonov Azamat Alisher o‘g‘li
A26: 2-toifali mutaxassis | B26: 1 | C26: =+Лист4!$C$7 -> 6081100 | D26: =+B26*Лист4!$C$7 -> 6081100 | E26: 9 | F26: vakant
A27: Axborot tizimlarini sinovdan o'tkazish bo'yicha bosh mutaxassis | B27: 1 | C27: =+Лист4!$C$10 -> 7442800 | D27: =+B27*Лист4!$C$10 -> 7442800 | E27: 12 | F27: vakant
A28: Jami: | B28: =SUM(B23:B27) -> 5 | D28: =SUM(D23:D27) -> 35415800
A29: Ijro nazorati va murojaatlar bilan ishlash bo'limi(4.1.)
A30: Bo‘lim boshlig‘i | B30: 1 | C30: =+Лист4!$C$13 -> 8388800 | D30: =+B30*Лист4!$C$13 -> 8388800 | E30: 14 | F30: Saydazimova Ziyoda Taxirovna
A31: 2-toifali mutaxassis | B31: 1 | C31: =+Лист4!$C$7 -> 6081100 | D31: =+B31*Лист4!$C$7 -> 6081100 | E31: 9 | F31: Nurxodjayeva Gulnora To‘ychi qizi
A32: Jami: | B32: =SUM(B30:B31) -> 2 | D32: =SUM(D30:D31) -> 14469900
A33: Inson resurslarini rivojlantirish bo‘limi (5.1.)
A34: Bo‘lim boshlig‘i | B34: 1 | C34: =+Лист4!$C$13 -> 8388800 | D34: =+B34*Лист4!$C$13 -> 8388800 | E34: 14 | F34: Ismailova Nafisa Amangeldiyevna
A35: Bosh mutaxassis | B35: 1 | C35: =+Лист4!$C$10 -> 7442800 | D35: =+B35*Лист4!$C$10 -> 7442800 | E35: 12 | F35: vakant
A36: Jami: | B36: =SUM(B34:B35) -> 2 | D36: =SUM(D34:D35) -> 15831600
A37: Bosh yuriskonsult (6.1.) | B37: 1 | C37: =+Лист4!$C$13 -> 8388800 | D37: =+B37*Лист4!$C$13 -> 8388800 | E37: 14
A38: Korporativ maslahatchi-marketolog (7.1.) | B38: 1 | C38: =+Лист4!$C$9 -> 6978500 | D38: =+B38*Лист4!$C$9 -> 6978500 | E38: 11 | F38: Mamatqulov Yorqin Komiljon o'g'li
A39: Korrupsiyaga qarshi kurashish bo'yicha mutaxassis (8.1.) | B39: 1 | C39: =+Лист4!$C$9 -> 6978500 | D39: =+B39*Лист4!$C$9 -> 6978500 | E39: 11 | F39: Eshniyozov Jamshid To‘lqinovich
A40: Ishlar boshqarish bo'limi (9.1.)
A41: Ish boshqaruvchi | B41: 1 | C41: =+Лист4!$C$13 -> 8388800 | D41: =+B41*Лист4!$C$13 -> 8388800 | E41: 14 | F41: Abdukarimov Abduvali Abdug‘ani o‘g‘li
A42: Ombor mudiri | B42: 1 | C42: =+Лист4!C5 -> 5214800 | D42: =+Лист4!C22 -> 3476600 | E42: 7 | F42: Sa’dullayev Axrorxo‘ja Ubaydulla o‘g‘li
A43: Haydovchi 1-smena ( 1,5 smena) | B43: 1 | C43: =+Лист4!C21*1.5 -> 3465000 | D43: =+B44*Лист4!C21*1.5 -> 3465000 | E43: 1 | F43: Azimboyev Akobir Akrom o'g'li
A44: Haydovchi 1-smena ( 1,5 smena) | B44: 1 | C44: =+Лист4!C21*1.5 -> 3465000 | D44: =+B44*Лист4!C21*1.5 -> 3465000 | E44: 1 | F44: Mirabbosov Miraziz Forxod o‘g‘li
A45: Jami: | B45: =SUM(B41:B44) -> 4 | D45: =SUM(D41:D44) -> 18795400
A46: Call markaz (10.1.)
...

Sheet Лист4
C1: Koeffitsiyent
A2: MHTEKM | B2: 1155000 | C2: 3
A3: Lavozim | B3: Shtat | C3: Oklad | D3: Razryad
A4: Haydovchi 1-smena ( 1,5 smena) | B4: 1 | C4: 3465000 | D4: 1 | E4: 0 | F4: =+E4*C4 -> 0
A5: Ombor mudiri | B5: 1 | C5: 5214800 | D5: 7 | E5: 1 | F5: =+E5*C5 -> 5214800
A6: 3-toifali mutaxassis | B6: 1 | C6: 5648000 | D6: 8 | E6: 15 | F6: =+E6*C6 -> 84720000
A7: 2-toifali mutaxassis | B7: 1 | C7: 6081100 | D7: 9 | E7: 23 | F7: =+E7*C7 -> 139865300
A8: 1-toifali mutaxassis | B8: 1 | C8: 6524600 | D8: 10 | E8: 44 | F8: =+E8*C8 -> 287082400
A9: Korporativ maslahatchi-marketolog | B9: 1 | C9: 6978500 | D9: 11 | E9: 31 | F9: =+E9*C9 -> 216333500
A10: Bosh mutaxassis | B10: 1 | C10: 7442800 | D10: 12 | E10: 16 | F10: =+E10*C10 -> 119084800
A11: Bo‘lim boshlig‘i o‘rinbosari | B11: 1 | C11: 7914100 | D11: 13 | E11: 10 | F11: =+E11*C11 -> 79141000
A12: Bosh yuriskonsult | B12: 1 | C12: 8388800 | D12: 14 | E12: 1 | F12: =+E12*C12 -> 8388800
A13: Bo‘lim boshlig‘i | B13: 1 | C13: 8388800 | D13: 14 | E13: 15 | F13: =+E13*C13 -> 125832000
A14: Direktorning birinchi o‘rinbosari | B14: 1 | C14: 8873900 | D14: 15 | E14: 1 | F14: =+E14*C14 -> 8873900
A15: Direktor o‘rinbosari | B15: 1 | C15: 8430300 | D15: 15 | E15: 2 | F15: =+E15*C15 -> 16860600
A16: Direktor | B16: 1 | C16: 9369400 | D16: 16 | E16: 1 | F16: =+E16*C16 -> 9369400
E17: =SUM(E4:E16) -> 160 | F17: =SUM(F4:F16) -> 1100766500
C18: Koeffitsiyent
A19: MHTEKM | B19: 1155000 | C19: 2
A20: Lavozim | B20: Shtat | C20: Oklad | D20: Razryad
A21: Haydovchi 1-smena ( 1,5 smena) | B21: 1 | C21: 2310000 | D21: 1 | E21: 3 | F21: =+E21*C21 -> 6930000
A22: Ombor mudiri | B22: 1 | C22: 3476600 | D22: 7 | E22: 0 | F22: =+E22*C22 -> 0
A23: 3-toifali mutaxassis | B23: 1 | C23: 3765300 | D23: 8 | E23: 6 | F23: =+E23*C23 -> 22591800
A24: 2-toifali mutaxassis | B24: 1 | C24: 4054100 | D24: 9 | E24: 9 | F24: =+E24*C24 -> 36486900
A25: 1-toifali mutaxassis | B25: 1 | C25: 4349700 | D25: 10 | E25: 8 | F25: =+E25*C25 -> 34797600
A26: Yetakchi mutaxassis | B26: 1 | C26: 4652300 | D26: 11 | E26: 15 | F26: =+E26*C26 -> 69784500
A27: Bosh mutaxassis | B27: 1 | C27: 4961900 | D27: 12 | E27: 0 | F27: =+E27*C27 -> 0
A28: Bo'lim boshlig'i o'rinbosari | B28: 1 | C28: 5276000 | D28: 13 | E28: 1 | F28: =+E28*C28 -> 5276000
A29: Bo‘lim boshlig‘i | B29: 1 | C29: 5592500 | D29: 14 | E29: 1 | F29: =+E29*C29 -> 5592500
E30: =SUM(E21:E29) -> 43 | F30: =SUM(F21:F29) -> 181459300
F32: =+F17+F30-'Лист1 (2)'!D271 -> 89364600

Sheet Лист1
A6: O‘zbekiston Respublikasi Iqtisodiyot va moliya vazirligi huzuridagi Axborot texnologiyalari markazi DUKning
A7: SHTAT JADVALI
C8: 01.01.2025 dan kuchga kiradi | L8: 01.12.2023 dan kuchga kiradi
A9: Tarkibiy tuzilmalarning nomi va lavozimlar nomi | B9: Shtat birliklarining soni | C9: Shtat jadvali bo'yicha bir oylik ish haqi (so'm) | D9: Razryad | L9: Shtat jadvali bo'yicha bir oylik ish haqi (so'm)
A10: 1 | B10: 2 | C10: 4 | D10: 3 | L10: 4
A11: Rahbariyat (1)
A12: Direktor | B12: 1 | C12: =ROUND(L12/100,0)*100 -> 9369400 | D12: 16 | E12: 8517600 | F12: =+#REF!*#REF!*G12 -> #REF! | G12: 2.704 | I12: =ROUND(L12/100,0)*100 -> 9369400 | L12: 9369360 | AM12: =VLOOKUP(D12,AN:AO,2,0)*B12 -> #N/A | AO12: 16 | AP12: 1000
A13: Direktorning birinchi o‘rinbosari | B13: 1 | C13: =ROUND(L13/100,0)*100 -> 8873900 | D13: 15 | E13: 8067200 | F13: =+#REF!*#REF!*G13 -> #REF! | G13: 2.561 | I13: =ROUND(L13/100,0)*100 -> 8873900 | L13: 8873865
A14: Direktor o‘rinbosari | B14: 1 | C14: =ROUND(L14/100,0)*100 -> 8430300 | D14: 15 | E14: 7664000 | F14: =+#REF!*#REF!*G14 -> #REF! | G14: 2.433 | I14: =ROUND(L14/100,0)*100 -> 8430300 | L14: 8430345
A15: Jami: | B15: =SUM(B12:B14) -> 3 | C15: =SUM(C12:C14) -> 26673600 | L15: =SUM(L12:L14) -> 26673570
A16: Moliya va iqtisod bo‘limi (2)
A17: Bo‘lim boshlig‘i-Bosh buxgalter | B17: 1 | C17: =ROUND(L17/100,0)*100 -> 8388800 | D17: 14 | E17: 7626200 | F17: =+#REF!*#REF!*G17 -> #REF! | G17: 2.421 | L17: 8388765
A18: Bo‘lim boshlig‘i o‘rinbosari-Bosh buxgalter o‘rinbosari | B18: 1 | C18: =ROUND(L18/100,0)*100 -> 7914100 | D18: 13 | E18: 7194600 | F18: =+#REF!*#REF!*G18 -> #REF! | G18: 2.284 | L18: 7914060
A19: Bosh mutaxassis | B19: 1 | C19: =ROUND(L19/100,0)*100 -> 7442800 | D19: 12 | E19: 6344100 | F19: =+#REF!*#REF!*G19 -> #REF! | G19: 2.014 | L19: 7442820
A20: Bosh mutaxassis | B20: 1 | C20: =ROUND(L20/100,0)*100 -> 7442800 | D20: 12 | E20: 6344100 | F20: =+#REF!*#REF!*G20 -> #REF! | G20: 2.014 | L20: 7442820
A21: Jami: | B21: =SUM(B17:B20) -> 4 | C21: =SUM(C17:C20) -> 31188500 | L21: =SUM(L17:L20) -> 31188465
A22: Inson resurslarini rivojlantirish bo‘limi (3)
A23: Bo‘lim boshlig‘i | B23: 1 | C23: 8388800 | D23: 14
A24: Yetakchi mutaxassis | B24: 1 | C24: 6978500 | D24: 11
A25: Jami: | B25: =SUM(B23:B24) -> 2 | C25: =SUM(C23:C24) -> 15367300
A26: Rahbariyat qoshidagi apparat (4)
A27: Bosh yuriskonsult | B27: 1 | C27: =ROUND(L27/100,0)*100 -> 8388800 | D27: 14 | E27: 7626200 | F27: =+#REF!*#REF!*G27 -> #REF! | G27: 2.421 | L27: 8388765
A28: Korporativ maslahatchi-marketolog | B28: 1 | C28: =ROUND(L28/100,0)*100 -> 6978500 | D28: 11 | E28: 6344100 | F28: =+#REF!*#REF!*G28 -> #REF! | G28: 2.014 | L28: 6978510
A29: Korrupsiyaga qarshi kurashish bo'yicha mutaxassis | B29: 1 | C29: =ROUND(L29/100,0)*100 -> 6978500 | D29: 11 | E29: 6344100 | F29: =+#REF!*#REF!*G29 -> #REF! | G29: 2.014 | L29: 6978510
A30: Jami: | B30: =SUM(B27:B29) -> 3 | C30: =SUM(C27:C29) -> 22345800 | F30: =+#REF!*#REF!*G30 -> #REF! | L30: =SUM(L27:L29) -> 22345785
A31: Ishlar boshqarmasi (5)
A32: Ish boshqaruvchi | B32: 1 | C32: =ROUND(L32/100,0)*100 -> 8388800 | D32: 14 | E32: 7626200 | F32: =+#REF!*#REF!*G32 -> #REF! | G32: 2.421 | L32: 8388765
A33: Ombor mudiri | B33: 1 | C33: =ROUND(L33/100,0)*100 -> 5214800 | D33: 7 | E33: 4740800 | F33: =+#REF!*#REF!*G33 -> #REF! | G33: 1.505 | L33: 5214825
A34: Haydovchi 1-smena ( 1,5 smena) | B34: 2 | C34: =ROUND(L34/100,0)*100 -> 3465000 | D34: 1 | E34: 3150000 | F34: =+#REF!*#REF!*G34 -> #REF! | G34: 1 | L34: 3465000
A35: Jami: | B35: =SUM(B32:B34) -> 4 | C35: =SUM(C32:C34) -> 17068600 | L35: =SUM(L32:L34) -> 17068590
A36: Ijro nazorati va murojaatlar bilan ishlash bo'limi(6)
A37: Bo‘lim boshlig‘i | B37: 1 | C37: =ROUND(L37/100,0)*100 -> 8388800 | D37: 14 | E37: 7626200 | F37: =+#REF!*#REF!*G37 -> #REF! | G37: 2.421 | L37: 8388765
A38: 2-toifali mutaxassis | B38: 1 | C38: 6081100 | D38: 9
A39: Jami: | B39: =SUM(B37:B38) -> 2 | C39: =SUM(C37:C38) -> 14469900 | E39: 0 | L39: =SUM(L37:L38) -> 8388765
A40: Call markaz (7) | F40: =+#REF!*#REF!*G40 -> #REF!
A41: Call markaz boshlig‘i | B41: 1 | C41: =ROUND(L41/100,0)*100 -> 8388800 | D41: 14 | E41: 7626200 | F41: =+#REF!*#REF!*G41 -> #REF! | G41: 2.421 | L41: 8388765
A42: 1-toifali mutaxassis | B42: 1 | C42: 6524600 | D42: 10
A43: 1-toifali mutaxassis | B43: 1 | C43: 6524600 | D43: 10
A44: Jami: | B44: =SUM(B41:B43) -> 3 | C44: =SUM(C41:C43) -> 21438000 | E44: 0 | F44: =+#REF!*#REF!*G44 -> #REF! | L44: =SUM(L41:L43) -> 8388765
A45: Axborot va kiberxavfsizlikni ta'minlash bo'limi (8)
...

Sheet Лист2
A1: Haydovchi 1-smena ( 1,5 smena) | B1: 1 | C1: 1 | D1: 3150000 | E1: vakant | F1: 3150000 | G1: =+#REF!*#REF!*H1 -> #REF! | H1: 1
A2: Haydovchi 1-smena ( 1,5 smena) | B2: 1 | C2: 1 | D2: 3150000 | E2: Amirov Sardor G'ayratjon o‘g‘li | F2: 3150000 | G2: =+#REF!*#REF!*H2 -> #REF! | H2: 1
A3: Haydovchi 1-smena ( 1,5 smena) | B3: 1 | C3: 1 | D3: 3150000 | E3: Yusupov Dilshod Sattaraliyevich | F3: 3150000 | G3: =+#REF!*#REF!*H3 -> #REF! | H3: 1
A4: 1-toyifali texnik (Buxara) | B4: 1 | C4: 4 | D4: 3647700 | E4: Akramov Umidjon Isoq o‘g‘li | F4: 3647700 | G4: =+#REF!*#REF!*H4 -> #REF! | H4: 1.158
A5: Ombor mudiri | B5: 1 | C5: 7 | D5: 4740800 | E5: Sa’dullayev Axrorxo‘ja Ubaydulla o‘g‘li | F5: 4740800 | G5: =+#REF!*#REF!*H5 -> #REF! | H5: 1.505
A6: 3-toyifali mutaxassis | B6: 1 | C6: 8 | D6: 5134500 | E6: Ergashev Ismoiljon Sarvarjon o‘g‘li (0.5 st) | F6: 5134500 | G6: =+#REF!*#REF!*H6 -> #REF! | H6: 1.63
A7: 3-toifali mutaxassis | B7: 1 | C7: 8 | D7: 5134500 | E7: Ro'zibayev Ismoiljon To'lqinboy o'g'li | F7: 5134500 | G7: =+#REF!*#REF!*H7 -> #REF! | H7: 1.63
A8: Dizayner | B8: 1 | C8: 8 | D8: 5134500 | E8: Keldiboyev Javoxirbek Ilxomjon o‘g‘li | F8: 5134500 | G8: =+#REF!*#REF!*H8 -> #REF! | H8: 1.63
A9: 3-toyifali mutaxassis | B9: 1 | C9: 8 | D9: 5134500 | E9: Ozodjonov Mirabbosbek Isroiljon o‘g‘li | F9: 5134500 | G9: =+#REF!*#REF!*H9 -> #REF! | H9: 1.63
A10: 3-toyifali mutaxassis | B10: 1 | C10: 8 | D10: 5134500 | E10: Ismoilov Dilmurod Baxtiyor o‘g‘li | F10: 5134500 | G10: =+#REF!*#REF!*H10 -> #REF! | H10: 1.63
A11: 3-toyifali mutaxassis | B11: 1 | C11: 8 | D11: 5134500 | E11: Abdurasulov Uchqun Tulkin o‘g‘li | F11: 5134500 | G11: =+#REF!*#REF!*H11 -> #REF! | H11: 1.63
A12: 3-toyifali mutaxassis | B12: 1 | C12: 8 | D12: 5134500 | E12: Eshpo‘latov Kamol Ikrom o‘g‘li | F12: 5134500 | G12: =+#REF!*#REF!*H12 -> #REF! | H12: 1.63
... A16: 3-toyifali mutaxassis | B16: 1 | C16: 8 | D16: 5134500 | E16: Iskandarov Boburjon Shuhrat o‘g‘li | F16: 5134500 | G16: =+#REF!*#REF!*H16 -> #REF! | H16: 1.63
A17: 3-toifali mutaxassis | B17: 1 | C17: 8 | D17: 5134500 | E17: Hamdullayev Aminjon Zubaydullo o‘g‘li | F17: 5134500 | G17: =+#REF!*#REF!*H17 -> #REF! | H17: 1.63 | J17: =+D17*1.07 -> 5493915
A18: 3-toyifali mutaxassis | B18: 1 | C18: 8 | D18: 5134500 | E18: Holmuminov Sherxon Ziyadullayevich | F18: 5134500 | G18: =+#REF!*#REF!*H18 -> #REF! | H18: 1.63
A19: 3-toyifali mutaxassis | B19: 1 | C19: 8 | D19: 5134500 | E19: Asadullayev Behzodxo‘ja G‘ayrat o‘g‘li (0.5st) | F19: 5134500 | G19: =+#REF!*#REF!*H19 -> #REF! | H19: 1.63
A20: 3-toyifali mutaxassis | B20: 1 | C20: 8 | D20: 5134500 | E20: Ishmuxamedov Bexzod Alisherovich | F20: 5134500 | G20: =+#REF!*#REF!*H20 -> #REF! | H20: 1.63
A21: 3-toyifali mutaxassis | B21: 1 | C21: 8 | D21: 5134500 | E21: Kulayev Elnur Yakubovich | F21: 5134500 | G21: =+#REF!*#REF!*H21 -> #REF! | H21: 1.63
A22: 3-toyifali mutaxassis | B22: 1 | C22: 8 | D22: 5134500 | E22: Abduvahabov Nodirbek Abdulzoshim o'g'li | F22: 5134500 | G22: =+#REF!*#REF!*H22 -> #REF! | H22: 1.63
A23: 3-toyifali mutaxassis (Jizzax) | B23: 1 | C23: 8 | D23: 5134500 | E23: Usmonov Jahongir Nurulla o‘g‘li | F23: 5134500 | G23: =+#REF!*#REF!*H23 -> #REF! | H23: 1.63
A24: 3-toyifali mutaxassis (Surxandaryo) | B24: 1 | C24: 8 | D24: 5134500 | E24: Karimov Sa’dullo Ne’matullo o‘g‘li | F24: 5134500 | G24: =+#REF!*#REF!*H24 -> #REF! | H24: 1.63
A25: 3-toyifali mutaxassis (Jizzax) | B25: 1 | C25: 8 | D25: 5134500 | E25: Shodmonov Latif Xudayberdiyevich | F25: 5134500 | G25: =+#REF!*#REF!*H25 -> #REF! | H25: 1.63
A26: 3-toifali mutaxassis | B26: 1 | C26: 8 | D26: 5134500 | E26: Abdunabiyeva Zilola Abdusattor qizi | F26: 5134500 | G26: =+#REF!*#REF!*H26 -> #REF! | H26: 1.63
A27: 3-toifali mutaxassis | B27: 1 | C27: 8 | D27: 5134500 | E27: Raximdjanov Abdurazzoq Rovshan o'g'li | F27: 5134500 | G27: =+#REF!*#REF!*H27 -> #REF! | H27: 1.63
A28: 3-toyifali mutaxassis | B28: 1 | C28: 8 | D28: 5134500 | E28: Shoymardonov Eldor Saydullo o'g'li | F28: 5134500 | G28: =+#REF!*#REF!*H28 -> #REF! | H28: 1.63
A29: 2-toyifali mutaxassis | B29: 1 | C29: 9 | D29: 5528300 | E29: Xudayberdiyev Muxammad Azamatovich | F29: 5528300 | G29: =+#REF!*#REF!*H29 -> #REF! | H29: 1.755
... A183: Direktor | B183: 1 | C183: 16 | D183: 8517600 | E183: Atadjanov Murod Bekberganovich | F183: 8517600 | G183: =+#REF!*#REF!*H183 -> #REF! | H183: 2.704
D184: =SUM(D1:D183) -> 1148159900
A186: Inson resurslarini rivojlantirish bo'yicha bosh mutaxassis | D186: N.Ismailova
A188: Yetakchi buxgalter | D188: S. Egamberdiyev
